Workbook

Sheet Portada

Sheet Tablas y Filtros
A10: Torre | B10: Tipo | C10: Modelo | D10: Número de Serie | E10: Descripción | F10: Valor Bruto del Activo | G10: Nuevo o Usado
A11: Medio | B11: 2817 | C11: M49 | D11: 024DE82 | E11: SYSTEM Z10 EC | F11: 5122975.3 | G11: Nuevo
A12: Medio | B12: 3957 | C12: V06 | D12: 78H2884 | E12: VIRTUALIZATION ENGINE TS7740 | F12: 116532.47 | G12: Usado | I12: Criterio | J12: Respuesta
A13: Medio | B13: 3957 | C13: V06 | D13: 78H2919 | E13: VIRTUALIZATION ENGINE TS7740 | F13: 116532.47 | G13: Usado | I13: Valor Bruto de los Activos Nuevos | J13: 5442863
A14: Medio | B14: 3957 | C14: V06 | D14: 78H2829 | E14: VIRTUALIZATION ENGINE TS7740 | F14: 115572.39 | G14: Usado | I14: Valor Bruto de los Activos Usados | J14: 611945
A15: Medio | B15: 3956 | C15: CX7 | D15: 00B3676 | E15: TS7740 CACHE CONTROLLER | F15: 37496.07 | G15: Nuevo | I15: Total de activos con un valor menor a 10,000 USD cada uno | J15: 43
A16: Medio | B16: 3956 | C16: CX7 | D16: 00B3696 | E16: TS7740 CACHE CONTROLLER | F16: 37496.07 | G16: Nuevo | I16: Valor Bruto de todas las máquinas de la Torre Medio | J16: 6010264
A17: Medio | B17: 3956 | C17: CX7 | D17: 00B3938 | E17: TS7740 CACHE CONTROLLER | F17: 37496.07 | G17: Usado | I17: Activo de mayor valor | J17: SYSTEM Z10 EC
A18: Medio | B18: 3956 | C18: CX7 | D18: 00B3939 | E18: TS7740 CACHE CONTROLLER | F18: 37496.07 | G18: Usado
A19: Medio | B19: 3956 | C19: CX7 | D19: 00B3950 | E19: TS7740 CACHE CONTROLLER | F19: 37496.07 | G19: Usado
A20: Medio | B20: 3956 | C20: CX7 | D20: 00B3951 | E20: TS7740 CACHE CONTROLLER | F20: 37496.07 | G20: Usado
A21: Medio | B21: 3584 | C21: L23 | D21: 78A3328 | E21: ULTRIUM ANACONDA LIBRARY | F21: 31497 | G21: Nuevo
A22: Medio | B22: 3584 | C22: D23 | D22: 78D0528 | E22: ULTRIUM ANACONDA LIBRARY | F22: 17911.39 | G22: Nuevo
A23: Medio | B23: 3584 | C23: D23 | D23: 78D0632 | E23: ULTRIUM ANACONDA LIBRARY | F23: 17911.39 | G23: Nuevo
A24: Medio | B24: 3584 | C24: D23 | D24: 78D0974 | E24: ULTRIUM ANACONDA LIBRARY | F24: 17911.39 | G24: Nuevo
A25: Medio | B25: 3584 | C25: D23 | D25: 78D0282 | E25: ULTRIUM ANACONDA LIBRARY | F25: 17868.91 | G25: Nuevo
A26: Medio | B26: 3584 | C26: D23 | D26: 78D0637 | E26: ULTRIUM ANACONDA LIBRARY | F26: 17868.91 | G26: Nuevo
A27: Medio | B27: 1818 | C27: D1A | D27: 00K1Y5X | E27: ASSIGN=EXP5000 EXPANSION UNIT | F27: 15361.15 | G27: Nuevo
A28: Medio | B28: 1740 | C28: 710 | D28: 0000667 | E28: TOTALSTORAGE FASTT EXP700 | F28: 10524 | G28: Nuevo
A29: Medio | B29: 3952 | C29: F05 | D29: 7813534 | E29: ASSIGN TAPE FRAME | F29: 8644.41 | G29: Nuevo
... A52: Medio | B52: 1818 | C52: D1A | D52: 78K1TR7 | E52: ASSIGN=EXP5000 EXPANSION UNIT | F52: 5070.91 | G52: Usado
A53: Servicios | B53: Z814 | D53: TAAS199037329 | E53: PANDUIT NET-ACCESS SWITCH CABINET | F53: 3810.16 | G53: Nuevo
A54: Servicios | B54: Z811 | D54: TAAS199037326 | E54: PANDUIT NET-ACCESS SWITCH CABINET | F54: 3810.15 | G54: Usado
A55: Servicios | B55: Z812 | D55: TAAS199037327 | E55: PANDUIT NET-ACCESS SWITCH CABINET | F55: 3810.15 | G55: Usado
A56: Servicios | B56: Z813 | D56: TAAS199037328 | E56: PANDUIT NET-ACCESS SWITCH CABINET | F56: 3810.15 | G56: Nuevo
A57: Servicios | B57: Z810 | D57: TAAS199037325 | E57: PANDUIT NET-ACCESS SWITCH CABINET | F57: 3809.97 | G57: Usado
A58: Servicios | B58: Z809 | D58: TAAS199037324 | E58: PANDUIT NET-ACCESS SWITCH CABINET | F58: 3809.96 | G58: Usado
A59: Medio | B59: 2145 | C59: CF8 | D59: 00LTG0A | E59: SAN VOLUME CONTROLLER XSERIES | F59: 3774.54 | G59: Usado
A60: Medio | B60: 2145 | C60: CF8 | D60: 00LTCFA | E60: SAN VOLUME CONTROLLER XSERIES | F60: 3773.63 | G60: Usado
A61: Medio | B61: 2145 | C61: CF8 | D61: 75LRRMA | E61: SAN VOLUME CONTROLLER XSERIES | F61: 3773.63 | G61: Usado
A62: Medio | B62: 2805 | C62: MC5 | D62: 0012242 | E62: SYSTEM STORAGE PRODUCT. CENTER | F62: 3367 | G62: Nuevo
A63: Medio | B63: 2805 | C63: MC5 | D63: 7512419 | E63: SYSTEM STORAGE PRODUCT. CENTER | F63: 3367 | G63: Nuevo
A64: Servicios | B64: 4252 | C64: AC1 | D64: KQ60W8R | E64: 4252 AC1 - SERVER | F64: 2798.4 | G64: Usado
A65: Servicios | B65: 4252 | C65: AC1 | D65: KQ60W8T | E65: 4252 AC1 - SERVER | F65: 2798.4 | G65: Usado
A66: Servicios | B66: 4252 | C66: AC1 | D66: KQ60W8V | E66: 4252 AC1 - SERVER | F66: 2798.4 | G66: Usado
A67: Servicios | B67: 4252 | C67: AC1 | D67: KQ60W8W | E67: 4252 AC1 - SERVER | F67: 2798.4 | G67: Usado
A68: Servicios | B68: 4252 | C68: AC1 | D68: KQ60W8X | E68: 4252 AC1 - SERVER | F68: 2798.4 | G68: Usado
A69: Medio | B69: 2145 | C69: CF8 | D69: 00LRRMA | E69: SAN VOLUME CONTROLLER XSERIES | F69: 0 | G69: Usado
A70: Medio | B70: 2805 | C70: MC5 | D70: 0012419 | E70: SYSTEM STORAGE PRODUCT. CENTER | F70: 0 | G70: Nuevo
A71: Servicios | B71: 7947 | C71: AC1 | D71: KQYDBZH | E71: IBM SYSTEM X3650 | F71: 0 | G71: Usado

Sheet Eco Mercado
A17: 18 de Enero | N17: 25 de Enero | AA17: 01 de Febrero | AN17: 08 de Febrero | BB17: 15 de Febrero | BP17: 22 de Febrero | CD17: 01 de Marzo
A18: Empresa | B18: Contacto | C18: Celular | D18: Teléfono | E18: Correo Electrónico | F18: Giro | G18: Vendedor | H18: Forma de Pago | I18: Precio | J18: Mesa | K18: Espacio | L18: Nuevo | N18: Empresa | O18: Contacto | P18: Celular | Q18: Teléfono | R18: Correo Electrónico | S18: Giro | T18: Vendedor | U18: Forma de Pago | V18: Precio | W18: Mesa | X18: Espacio | Y18: Nuevo | AA18: Empresa | AB18: Contacto | AC18: Celular | AD18: Teléfono | AE18: Correo Electrónico | AF18: Giro | AG18: Vendedor | AH18: Forma de Pago | AI18: Precio | AJ18: Mesa | AK18: Espacio | AL18: Nuevo | AN18: Empresa | AO18: Contacto | AP18: Celular | AQ18: Teléfono | AR18: Correo Electrónico | AS18: Giro | AT18: Vendedor | AU18: Forma de Pago | AV18: Precio | AW18: Mesa | AX18: Espacio | AY18: Nuevo | AZ18: Perforación | BB18: Empresa | BC18: Contacto | BD18: Celular | BE18: Teléfono | BF18: Correo Electrónico | BG18: Giro | BH18: Vendedor | BI18: Forma de Pago | BJ18: Precio | BK18: Mesa | BL18: Espacio | BM18: Nuevo | BN18: Perforación | BP18: Empresa | BQ18: Contacto | BR18: Celular | BS18: Teléfono | BT18: Correo Electrónico | BU18: Giro | BV18: Vendedor | BW18: Forma de Pago | BX18: Precio | BY18: Mesa | BZ18: Espacio | CA18: Nuevo | CB18: Perforación | CD18: Empresa | CE18: Contacto | CF18: Celular | CG18: Teléfono | CH18: Correo Electrónico | CI18: Giro | CJ18: Vendedor | CK18: Forma de Pago | CL18: Precio | CM18: Mesa | CN18: Espacio | CO18: Nuevo | CP18: Perforación
A19: A Long Asian Gourmet | B19: Aaron Disler | C19: 3314819409 | E19: a_long_asian_gourmet@yahoo.com | F19: Empanadas chinas, dumplings | H19: Banco | I19: 232 | J19: Media | K19: 18a | N19: 4to de Baño | O19: Gabriela Jiménez | P19: 3311488590 | Q19: 38135725 | R19: gabiwork@hotmail.com | S19: jabones naturales, cepillos | U19: Efectivo | V19: 375 | W19: Completa | X19: 5 | AA19: 4to de Baño | AB19: Gabriela Jiménez | AC19: 3311488590 | AD19: 38135725 | AE19: gabiwork@hotmail.com | AF19: jabones naturales, cepillos | AH19: Efectivo | AI19: 375 | AJ19: Completa | AK19: 5 | AN19: A Long Asian Gourmet | AO19: Aaron Disler | AP19: 3314819409 | AR19: a_long_asian_gourmet@yahoo.com | AS19: Empanadas chinas, dumplings | AU19: Transferencia | AV19: 232 | AW19: Media | AX19: 30a | AZ19: 1 | BB19: 4to de Baño | BC19: Gabriela Jiménez | BD19: 3311488590 | BE19: 38135725 | BF19: gabiwork@hotmail.com | BG19: jabones naturales, cepillos | BI19: Efectivo | BJ19: 375 | BK19: Completa | BL19: 5 | BN19: 1 | BP19: 4to de Baño | BQ19: Gabriela Jiménez | BR19: 3311488590 | BS19: 38135725 | BT19: gabiwork@hotmail.com | BU19: jabones naturales, cepillos | BW19: Efectivo | BX19: 375 | BY19: Completa | BZ19: 16 | CB19: 2 | CD19: A Long Asian Gourmet | CE19: Aaron Disler | CF19: 3314819409 | CH19: a_long_asian_gourmet@yahoo.com | CI19: Empanadas chinas, dumplings | CK19: Transferencia | CL19: 232 | CM19: Media | CN19: 5b | CP19: 4
A20: AMO Cacao | B20: Fernel Bobadilla | C20: 3315337212 | E20: fernelbp@hotmail.com | F20: Chocolate. | H20: Efectivo | I20: 187.5 | J20: Media | K20: 17b | N20: AMO Cacao | O20: Fernel Bobadilla | P20: 3315337212 | R20: fernelbp@hotmail.com | S20: Chocolate. | U20: Efectivo | V20: 187.5 | W20: Media | X20: 17b | AA20: A Long Asian Gourmet | AB20: Aaron Disler | AC20: 3314819409 | AE20: a_long_asian_gourmet@yahoo.com | AF20: Empanadas chinas, dumplings | AH20: Efectivo | AI20: 200 | AJ20: Media | AK20: 23 | AN20: AMO Cacao | AO20: Fernel Bobadilla | AP20: 3315337212 | AR20: fernelbp@hotmail.com | AS20: Chocolate. | AU20: Efectivo | AV20: 187.5 | AW20: Media | AX20: 18b | AZ20: 1 | BB20: A Long Asian Gourmet | BC20: Aaron Disler | BD20: 3314819409 | BF20: a_long_asian_gourmet@yahoo.com | BG20: Empanadas chinas, dumplings | BI20: Banco | BJ20: 232 | BK20: Media | BL20: 31a | BN20: 2 | BP20: A Long Asian Gourmet | BQ20: Aaron Disler | BR20: 3314819409 | BT20: a_long_asian_gourmet@yahoo.com | BU20: Empanadas chinas, dumplings | BW20: Banco | BX20: 232 | BY20: Media | BZ20: 32b | CB20: 3 | CD20: Angie Inzúa | CE20: Angie Inzúa | CF20: 3314174876 | CH20: u2angie@hotmail.com | CI20: collares hechos a mano | CK20: Efectivo | CL20: 187.5 | CM20: Media | CN20: 13b | CP20: 4
A21: Ángeles Queso | B21: Ángeles Queso | C21: 3335591738 | E21: mangelesmunoz@me.com | F21: Quesos, aderezos. | H21: Efectivo | I21: 200 | J21: Media | K21: 3a | N21: Ángeles Queso | O21: Ángeles Queso | P21: 3335591738 | R21: mangelesmunoz@me.com | S21: Quesos, aderezos. | U21: Efectivo | V21: 200 | W21: Media | X21: 3a | AA21: AMO Cacao | AB21: Fernel Bobadilla | AC21: 3315337212 | AE21: fernelbp@hotmail.com | AF21: Chocolate. | AH21: Efectivo | AI21: 187.5 | AJ21: Media | AK21: 17b | AN21: Ángeles Queso | AO21: Ángeles Queso | AP21: 3335591738 | AR21: mangelesmunoz@me.com | AS21: Quesos, aderezos. | AU21: Efectivo | AV21: 100 | AW21: Media | AX21: 11b | AZ21: 1 | BB21: Angie Inzúa | BC21: Angie Inzúa | BD21: 3314174876 | BF21: u2angie@hotmail.com | BG21: collares hechos a mano | BI21: Efectivo | BJ21: 187.5 | BK21: Media | BL21: 13a | BN21: 2 | BP21: AMO Cacao | BQ21: Fernel Bobadilla | BR21: 3315337212 | BT21: fernelbp@hotmail.com | BU21: Chocolate. | BW21: Efectivo | BX21: 190 | BY21: Media | BZ21: 31b | CB21: 2 | CD21: Bambuk | CE21: Santiago Álvarez | CF21: 3338210776 | CH21: alvarezv.santiago@gmail.com | CI21: Fundas de madera para celular | CK21: Efectivo | CL21: 187.5 | CM21: Media | CN21: 9b | CP21: 4
A22: Angie Inzúa | B22: Angie Inzúa | C22: 3314174876 | E22: u2angie@hotmail.com | F22: collares hechos a mano | H22: Efectivo | I22: 187.5 | J22: Media | K22: 13b | N22: Angie Inzúa | O22: Angie Inzúa | P22: 3314174876 | R22: u2angie@hotmail.com | S22: collares hechos a mano | U22: Efectivo | V22: 187.5 | W22: Media | X22: 14a | AA22: Ángeles Queso | AB22: Ángeles Queso | AC22: 3335591738 | AE22: mangelesmunoz@me.com | AF22: Quesos, aderezos. | AH22: Efectivo | AI22: 100 | AJ22: Media | AK22: 3a | AN22: Angie Inzúa | AO22: Angie Inzúa | AP22: 3314174876 | AR22: u2angie@hotmail.com | AS22: collares hechos a mano | AU22: Efectivo | AV22: 187.5 | AW22: Media | AX22: 13a | AZ22: 1 | BB22: Armonía Magnética | BC22: Pilar Ramírez | BD22: 3314177243 | BF22: armoniamagnetica@gmail.com | BI22: Efectivo | BJ22: 200 | BK22: Media | BL22: 20a | BN22: 2 | BP22: Angie Inzúa | BQ22: Angie Inzúa | BR22: 3314174876 | BT22: u2angie@hotmail.com | BU22: collares hechos a mano | BW22: Efectivo | BX22: 187.5 | BY22: Media | BZ22: 13a | CB22: 3 | CD22: Celestial | CE22: Héctor Fajardo | CF22: 3311424137 | CG22: 36159547 | CH22: hectorfajardo1@icloud.com | CI22: especias, pesto, aceite de oliva, sal de mar, tomate deshidratado | CK22: Efectivo | CL22: 200 | CM22: Media | CN22: 3b | CP22: 4
A23: Armonía Magnética | B23: Pilar Ramírez | C23: 3314117724 | E23: armoniamagnetica@gmail.com | H23: Efectivo | I23: 200 | J23: Media | K23: 10a | N23: Avogratto | O23: Lorena Ortiz | P23: 3314872679 | R23: lpatri1304@hotmail.com | S23: Aceite de aguacate. | U23: Anticipado | V23: 0 | W23: Media | X23: 17a | AA23: Angie Inzúa | AB23: Angie Inzúa | AC23: 3314174876 | AE23: u2angie@hotmail.com | AF23: collares hechos a mano | AH23: Efectivo | AI23: 187.5 | AJ23: Media | AK23: 14a | AN23: Armonía Magnética | AO23: Pilar Ramírez | AP23: 3314177243 | AR23: armoniamagnetica@gmail.com | AU23: Efectivo | AV23: 200 | AW23: Media | AX23: 14b | AZ23: 1 | BB23: Aura Rodriguez | BC23: Aura Rodriguez | BD23: 3317711276 | BF23: aura.xacnicte@gmail.com | BG23: Pinturas | BI23: Efectivo | BJ23: 200 | BK23: Media | BL23: 21b | BN23: 2 | BP23: Armonía Magnética | BQ23: Pilar Ramírez | BR23: 3314177243 | BT23: armoniamagnetica@gmail.com | BW23: Efectivo | BX23: 200 | BY23: Media | BZ23: 28b | CB23: 3 | CD23: Che Sen | CE23: Martha Rojo de la Vega | CF23: 3339559274 | CH23: contacto.chesen@gmail.com | CI23: granola, nueces | CK23: Efectivo | CL23: 187.5 | CM23: Media | CN23: 5a | CP23: 4
A24: Avogratto | B24: Lorena Ortiz | C24: 3314872679 | E24: lpatri1304@hotmail.com | F24: Aceite de aguacate. | H24: Anticipado | I24: 0 | J24: Media | K24: 17a | N24: Azafrán Boxes | O24: Leonardo Parra | P24: 3331294429 | R24: azafranboxes@gmail.com | S24: cajas fuertes en forma de libros | T24: Sofía | U24: pendiente | V24: 200 | W24: Media | X24: 21b | AA24: Aura Rodriguez | AB24: Aura Rodriguez | AC24: 3317711276 | AE24: aura.xacnicte@gmail.com | AF24: Pinturas | AH24: Efectivo | AI24: 200 | AJ24: Media | AK24: 21b | AN24: Aura Rodriguez | AO24: Aura Rodriguez | AP24: 3317711276 | AR24: aura.xacnicte@gmail.com | AS24: Pinturas | AU24: Efectivo | AV24: 200 | AW24: Media | AX24: 20b | AZ24: 1 | BB24: Avogratto | BC24: Lorena Ortiz | BD24: 3314872679 | BF24: lpatri1304@hotmail.com | BG24: Aceite de aguacate. | BI24: Anticipado | BJ24: 0 | BK24: Media | BL24: 17b | BN24: 2 | BP24: Aura Rodriguez | BQ24: Aura Rodriguez | BR24: 3317711276 | BT24: aura.xacnicte@gmail.com | BU24: Pinturas | BW24: Efectivo | BX24: 200 | BY24: Media | BZ24: 21b | CB24: 3 | CD24: Cosas para Gato | CE24: Alejandra Montes de Oca | CF24: 3312148735 | CG24: 18160501 | CH24: cosasparagatos@gmail.com | CI24: Artículos para mascotas | CK24: Efectivo | CL24: 200 | CM24: Ninguna | CP24: 0
A25: Bambuk | B25: Santiago Álvarez | C25: 3338210776 | E25: alvarezv.santiago@gmail.com | F25: fundas de madera para celular | H25: Efectivo | I25: 187.5 | J25: Media | K25: 9b | N25: Bambuk | O25: Santiago Álvarez | P25: 3338210776 | R25: alvarezv.santiago@gmail.com | S25: fundas de madera para celular | U25: Efectivo | V25: 187.5 | W25: Media | X25: 9b | AA25: Avogratto | AB25: Lorena Ortiz | AC25: 3314872679 | AE25: lpatri1304@hotmail.com | AF25: Aceite de aguacate. | AH25: Efectivo | AI25: 0 | AJ25: Media | AK25: 18b | AN25: Avogratto | AO25: Lorena Ortiz | AP25: 3314872679 | AR25: lpatri1304@hotmail.com | AS25: Aceite de aguacate. | AU25: Anticipado | AV25: 0 | AW25: Media | AX25: 17b | AZ25: 1 | BB25: Bambuk | BC25: Santiago Álvarez | BD25: 3338210776 | BF25: alvarezv.santiago@gmail.com | BG25: Fundas de madera para celular | BI25: Efectivo | BJ25: 187.5 | BK25: Media | BL25: 9b | BN25: 2 | BP25: Azafrán Boxes | BQ25: Leonardo Parra | BR25: 3331294429 | BT25: azafranboxes@gmail.com | BU25: cajas fuertes en forma de libros | BW25: Pendiente | BX25: 250 | BY25: Media | BZ25: 35a | CB25: 1 | CD25: D'Talles y Bisutería | CE25: Adrián Martínez | CF25: 3310932686 | CH25: dtalle@hotmail.com | CI25: relojes, pulseras, llaveros, accesorios | CJ25: Sofía | CK25: Efectivo | CL25: 187.5 | CM25: Media | CN25: 6b | CP25: 4
A26: Bernardo Brocher | B26: Bernardo Brocher | C26: 3331979100 | E26: barneybrocher@hotmail.com | F26: Empanadas y embutidos. | H26: Efectivo | I26: 200 | J26: Media | K26: 11a | N26: Bio Zen | O26: Areli Arámbula | P26: 3310508101 | R26: karenalonsogarza@gmail.com | S26: Desodorante de piedra. | T26: Sofía | X26: 2 | AA26: Bambuk | AB26: Santiago Álvarez | AC26: 3338210776 | AE26: alvarezv.santiago@gmail.com | AF26: fundas de madera para celular | AH26: Efectivo | AI26: 187.5 | AJ26: Media | AK26: 9b | AN26: Bambú | AO26: Ofelia Fernández | AP26: 3315716643 | AQ26: 33303837 | AR26: bambualmohadasterapeuticas@gmail.com | AS26: Almohadas terapéuticas. | AU26: Efectivo | AV26: 375 | AW26: Completa | AX26: 5 | AZ26: 1 | BB26: Biorganicos FG | BC26: Flor López Bon | BD26: 333 6622520 | BE26: 36272470 | BF26: biorganicosfg@gmail.com | BG26: verduras orgánicas | BI26: Efectivo | BJ26: 60 | BK26: Completa | BL26: 11 | BN26: 1 | BP26: Bambú | BQ26: Ofelia Fernández | BR26: 3315716643 | BS26: 33303837 | BT26: bambualmohadasterapeuticas@gmail.com | BU26: Almohadas terapéuticas. | BW26: Efectivo | BX26: 375 | BY26: Completa | BZ26: 17 | CB26: 2 | CD26: Den Maya Invernaderos | CE26: Yesica Delgado Díaz | CF26: 3311856312 | CH26: yeska_27@hotmail.com | CI26: Plantas, hierbas aromáticas, flores, árboles en maceta. | CK26: Efectivo | CL26: 375 | CM26: Completa | CN26: 1 | CP26: 4
A27: Bitácora | B27: Mario de Santos | C27: 3336761496 | E27: mdesantosj@gmail.com | F27: Libretas | G27: Sofía | H27: Efectivo | I27: 187.5 | J27: Media | K27: 21b | N27: Bitácora | O27: Mario de Santos | P27: 3336761496 | R27: mdesantosj@gmail.com | S27: Libretas | T27: Sofía | U27: Efectivo | V27: 187.5 | W27: Media | X27: 6b | AA27: Bernardo Brocher | AB27: Bernardo Brocher | AC27: 3331979100 | AE27: barneybrocher@hotmail.com | AF27: Empanadas y embutidos. | AH27: Efectivo | AI27: 200 | AJ27: Media | AK27: 8a | AN27: Bambuk | AO27: Santiago Álvarez | AP27: 3338210776 | AR27: alvarezv.santiago@gmail.com | AS27: fundas de madera para celular | AU27: Efectivo | AV27: 187.5 | AW27: Media | AX27: 9b | AZ27: 1 | BB27: Celestial | BC27: Héctor Fajardo | BD27: 3311424137 | BE27: 36159547 | BF27: hectorfajardo1@icloud.com | BG27: especias, pesto, aceite de oliva, sal de mar, tomate deshidratado | BI27: Efectivo | BJ27: 200 | BK27: Media | BL27: 3b | BN27: 2 | BP27: Bambuk | BQ27: Santiago Álvarez | BR27: 3338210776 | BT27: alvarezv.santiago@gmail.com | BU27: Fundas de madera para celular | BW27: Efectivo | BX27: 187.5 | BY27: Media | BZ27: 19a | CB27: 3 | CD27: Eclectic | CE27: Osvaldo López | CF27: 3312326066 | CH27: osvaldo_flb@hotmail.com | CI27: Playeras sublimadas | CJ27: Gonzalo | CK27: Falta | CL27: 60 | CM27: Media | CN27: 16a | CP27: 2
A28: Celestial | B28: Héctor Fajardo | C28: 3311424137 | D28: 36159547 | E28: hectorfajardo1@icloud.com | F28: especias, pesto, aceite de oliva, sal de mar, tomate deshidratado | H28: Efectivo | I28: 200 | J28: Media | K28: 16a | N28: Celestial | O28: Héctor Fajardo | P28: 3311424137 | Q28: 36159547 | R28: hectorfajardo1@icloud.com | S28: especias, pesto, aceite de oliva, sal de mar, tomate deshidratado | U28: Efectivo | V28: 200 | W28: Media | X28: 3b | AA28: Bitácora | AB28: Mario de Santos | AC28: 3336761496 | AE28: mdesantosj@gmail.com | AF28: Libretas | AG28: Sofía | AH28: Efectivo | AI28: 187.5 | AJ28: Media | AK28: 6b | AN28: Bernardo Brocher | AO28: Bernardo Brocher | AP28: 3331979100 | AR28: barneybrocher@hotmail.com | AS28: Empanadas y embutidos. | AU28: Efectivo | AV28: 200 | AW28: Media | AX28: 11a | AZ28: 1 | BB28: Che Sen | BC28: Martha Rojo de la Vega | BD28: 3339559274 | BF28: contacto.chesen@gmail.com | BG28: granola, nueces | BI28: Efectivo | BJ28: 187.5 | BK28: Media | BL28: 16b | BN28: 2 | BP28: Biopiscinas | BQ28: Sandra Saldívar | BR28: 3310906593 | BT28: sandra.saldivar@gmail.com | BU28: Sustituto de cloro para albercas y para desinfectar | BV28: Sofía | BW28: Intercambio | BX28: 0 | BY28: Media | BZ28: 34b | CB28: 1 | CD28: Eclock | CE28: Edgar Torres | CF28: 3317246984 | CH28: eclock.relojes@hotmail.com | CI28: Relojes de madera | CK28: Efectivo | CL28: 200 | CM28: Media | CN28: 9a | CP28: 2
A29: Che Sen | B29: Martha Rojo de la Vega | C29: 3339559274 | E29: contacto.chesen@gmail.com | F29: granola, nueces | H29: Banco | I29: 232 | J29: Media | K29: 9a | N29: Che Sen | O29: Martha Rojo de la Vega | P29: 3339559274 | R29: contacto.chesen@gmail.com | S29: granola, nueces | U29: Efectivo | V29: 200 | W29: Media | X29: 9a | AA29: Celestial | AB29: Héctor Fajardo | AC29: 3311424137 | AD29: 36159547 | AE29: hectorfajardo1@icloud.com | AF29: especias, pesto, aceite de oliva, sal de mar, tomate deshidratado | AH29: Efectivo | AI29: 200 | AJ29: Media | AK29: 3b | AN29: Bitácora | AO29: Mario de Santos | AP29: 3336761496 | AR29: mdesantosj@gmail.com | AS29: Libretas | AT29: Sofía | AU29: Efectivo | AV29: 187.5 | AW29: Media | AX29: 32a | AZ29: 1 | BB29: Da Du Didactics | BC29: Ana Elena Peinado Olvera | BD29: 3338304373 | BE29: 10990107 | BF29: anel.dragonas@gmail.com | BG29: juguetes creativos y didácticos de madera | BI29: Intercambio | BJ29: 0 | BK29: Media | BL29: 13b | BN29: 2 | BP29: Celestial | BQ29: Héctor Fajardo | BR29: 3311424137 | BS29: 36159547 | BT29: hectorfajardo1@icloud.com | BU29: especias, pesto, aceite de oliva, sal de mar, tomate deshidratado | BW29: Efectivo | BX29: 200 | BY29: Media | BZ29: 9b | CB29: 3 | CD29: Enjoy Time | CE29: Francisco Valencia | CF29: 3339582509 | CI29: Tisanas frutales y moringa. | CK29: Efectivo | CL29: 400 | CM29: Completa | CN29: 10 | CP29: 4
A30: Da Du Didactics | B30: Ana Elena Peinado Olvera | C30: 3338304373 | D30: 10990107 | E30: anel.dragonas@gmail.com | F30: juguetes creativos y didácticos de madera | H30: Banco | I30: 870 | J30: Media | K30: 13a | N30: Cocina Icaza | O30: Mónica Icaza | P30: 3333778377 | R30: cocinaicaza@gmail.com | S30: Salsas y aderezos. | T30: Sofía | U30: Efectivo | V30: 200 | W30: Media | X30: 10a | AA30: Coco Energy | AB30: Celia Delgadillo | AC30: 3311346872 | AD30: 36988513 | AE30: cedel4@hotmail.com | AF30: aceite de coco | AH30: Efectivo | AI30: 0 | AJ30: Media | AK30: 20 | AN30: Celestial | AO30: Héctor Fajardo | AP30: 3311424137 | AQ30: 36159547 | AR30: hectorfajardo1@icloud.com | AS30: especias, pesto, aceite de oliva, sal de mar, tomate deshidratado | AU30: Efectivo | AV30: 200 | AW30: Media | AX30: 3b | AZ30: 1 | BB30: Den Maya Invernaderos | BC30: Yesica Delgado Díaz | BD30: 3311856312 | BF30: yeska_27@hotmail.com | BG30: Plantas, hierbas aromáticas, flores, árboles en maceta. | BI30: Efectivo | BJ30: 375 | BK30: Completa | BL30: 1 | BN30: 2 | BP30: Che Sen | BQ30: Martha Rojo de la Vega | BR30: 3339559274 | BT30: contacto.chesen@gmail.com | BU30: granola, nueces | BW30: Falta | BX30: 187.5 | BY30: Media | BZ30: 31a | CB30: 3 | CD30: EVOO | CE30: Margarita Rodriguez | CF30: 3313600806 | CH30: dramarrod@hotmail.com | CK30: Efectivo | CL30: 50 | CM30: Completa | CN30: 11 | CP30: 4
A31: Donaji | B31: Nicole Velez Rodriguez | C31: 3319765566 | E31: donajiproductodeoaxaca@gmail.com | F31: mole, café, chocolate, salsas | H31: Efectivo | I31: 250 | J31: Media | K31: Falta | N31: Da Du Didactics | O31: Ana Elena Peinado Olvera | P31: 3338304373 | Q31: 10990107 | R31: anel.dragonas@gmail.com | S31: juguetes creativos y didácticos de madera | U31: Banco | V31: 870 | W31: Media | X31: 13a | AA31: Da Du Didactics | AB31: Ana Elena Peinado Olvera | AC31: 3338304373 | AD31: 10990107 | AE31: anel.dragonas@gmail.com | AF31: juguetes creativos y didácticos de madera | AH31: Banco | AI31: 187.5 | AJ31: Media | AK31: 13b | AN31: Che Sen | AO31: Martha Rojo de la Vega | AP31: 3339559274 | AR31: contacto.chesen@gmail.com | AS31: granola, nueces | AU31: Efectivo | AV31: 187.5 | AW31: Media | AX31: 16b | AZ31: 1 | BB31: D'Talles y Bisutería | BC31: Adrián Martínez | BD31: 3310932686 | BF31: dtalle@hotmail.com | BG31: relojes, pulseras, llaveros, accesorios | BH31: Sofía | BI31: Efectivo | BJ31: 187.5 | BK31: Media | BL31: 6b | BN31: 2 | BP31: Claudia Amador Bisutería | BQ31: Claudia Amador | BR31: 3311092077 | BS31: 16773310 | BT31: clau_75_mx@hotmail.com | BU31: bisutería artesanal | BW31: Efectivo | BX31: 200 | BY31: Media | BZ31: 23b | CB31: 1 | CD31: Gusto Gourmet | CE31: Karen Alonso | CF31: 3314412645 | CI31: Salsas, verdura botanera, chimichurri, pesto. | CK31: Efectivo | CL31: 200 | CM31: Media | CN31: 3a | CP31: 4
A32: Eclock | B32: Edgar Torres | C32: 3317246984 | E32: eclock.relojes@hotmail.com | F32: Relojes de madera | H32: Efectivo | I32: 200 | J32: Media | K32: 21a | N32: Den Maya Invernaderos | O32: Yesica Delgado Díaz | P32: 3311856312 | R32: yeska_27@hotmail.com | S32: Plantas, hierbas aromáticas, flores, árboles en maceta. | U32: Efectivo | V32: 1500 | W32: Completa | X32: 1 | AA32: Den Maya Invernaderos | AB32: Yesica Delgado Díaz | AC32: 3311856312 | AE32: yeska_27@hotmail.com | AF32: Plantas, hierbas aromáticas, flores, árboles en maceta. | AH32: Efectivo | AI32: 375 | AJ32: Completa | AK32: 1 | AN32: Da Du Didactics | AO32: Ana Elena Peinado Olvera | AP32: 3338304373 | AQ32: 10990107 | AR32: anel.dragonas@gmail.com | AS32: juguetes creativos y didácticos de madera | AU32: Banco | AV32: 187.5 | AW32: Media | AX32: 13b | AZ32: 1 | BB32: Eclock | BC32: Edgar Torres | BD32: 3317246984 | BF32: eclock.relojes@hotmail.com | BG32: Relojes de madera | BI32: Efectivo | BJ32: 200 | BK32: Media | BL32: 9a | BN32: 1 | BP32: Cocina Icaza | BQ32: Mónica Icaza | BR32: 3333778377 | BT32: cocinaicaza@gmail.com | BU32: Salsas y aderezos. | BW32: Efectivo | BX32: 125 | BY32: Media | BZ32: 19b | CB32: 1 | CD32: Itacate | CE32: Swannie Díaz de León | CF32: 3310967806 | CH32: yolohtli@gmail.com | CI32: Granola, hummus, tabule, pan. | CK32: Efectivo | CL32: 125 | CM32: Media | CN32: 14b | CP32: 2
A33: EVOO | B33: Margarita Rodriguez | C33: 3313600806 | E33: dramarrod@hotmail.com | H33: Intercambio | I33: 0 | J33: Completa | K33: 1 | N33: Detalles y Bisutería | O33: Adrián Martínez | P33: 3310932686 | R33: dtalle@hotmail.com | U33: Efectivo | V33: 250 | W33: Media | X33: 23a | AA33: Detalles y Bisutería | AB33: Adrián Martínez | AC33: 3310932686 | AE33: dtalle@hotmail.com | AF33: relojes, pulseras, llaveros, accesorios | AG33: Sofía | AH33: Efectivo | AI33: 187.5 | AJ33: Media | AK33: 6b | AN33: Den Maya Invernaderos | AO33: Yesica Delgado Díaz | AP33: 3311856312 | AR33: yeska_27@hotmail.com | AS33: Plantas, hierbas aromáticas, flores, árboles en maceta. | AU33: Efectivo | AV33: 375 | AW33: Completa | AX33: 1 | AZ33: 1 | BB33: Enjoy Time | BC33: Francisco Valencia | BD33: 3339582509 | BG33: Tisanas frutales y moringa. | BI33: Efectivo | BJ33: 400 | BK33: Completa | BL33: 10 | BN33: 2 | BP33: D'Talles y Bisutería | BQ33: Adrián Martínez | BR33: 3310932686 | BT33: dtalle@hotmail.com | BU33: relojes, pulseras, llaveros, accesorios | BV33: Sofía | BW33: Efectivo | BX33: 187.5 | BY33: Media | BZ33: 14b | CB33: 3 | CD33: Jamaitingas | CE33: Arlene Sánchez | CF33: 3334057358 | CH33: miryana23@hotmail.com | CI33: guisados a base de jamaica | CK33: Efectivo | CL33: 200 | CM33: Media | CN33: 15a | CP33: 4
A34: Frutas Vero | B34: Verónica Tolentino Espinoza | C34: 3314277826 | F34: Frutas orgánicas | H34: Efectivo | I34: 50 | J34: Completa | K34: 12 | N34: EVOO | O34: Margarita Rodriguez | P34: 3313600806 | R34: dramarrod@hotmail.com | T34: Margarita | U34: pendiente | V34: 50 | W34: Completa | X34: 22 | AA34: Eclock | AB34: Edgar Torres | AC34: 3317246984 | AE34: eclock.relojes@hotmail.com | AF34: Relojes de madera | AH34: Efectivo | AI34: 200 | AJ34: Media | AK34: 16b | AN34: D'Talles y Bisutería | AO34: Adrián Martínez | AP34: 3310932686 | AR34: dtalle@hotmail.com | AS34: relojes, pulseras, llaveros, accesorios | AT34: Sofía | AU34: Efectivo | AV34: 187.5 | AW34: Media | AX34: 6b | AZ34: 1 | BB34: EVOO | BC34: Margarita Rodriguez | BD34: 3313600806 | BF34: dramarrod@hotmail.com | BI34: Efectivo | BJ34: 50 | BK34: Completa | BL34: 30 | BN34: 2 | BP34: Da Du Didactics | BQ34: Ana Elena Peinado Olvera | BR34: 3338304373 | BS34: 10990107 | BT34: anel.dragonas@gmail.com | BU34: juguetes creativos y didácticos de madera | BW34: Pendiente | BX34: 187.5 | BY34: Media | BZ34: 13b | CB34: 3 | CD34: La Bee Organic | CE34: Luis Elizondo | CF34: 3331787364 | CH34: labeeorganic@gmail.com | CI34: bálsamo para labios | CK34: Efectivo | CL34: 200 | CM34: Media | CN34: 12a | CP34: 3
A35: Glow | B35: Alejandro Cantú | C35: 3317314958 | D35: 17314958 | E35: glowstore.07@gmail.com | F35: ropa de diseño independiente | H35: Efectivo | I35: 750 | J35: Media | K35: 14a | N35: Frutas Vero | O35: Verónica Tolentino Espinoza | P35: 3314277826 | S35: Frutas orgánicas | U35: Efectivo | V35: 50 | W35: Completa | X35: 12 | AA35: Enjoy Time | AB35: Francisco Valencia | AC35: 3339582509 | AF35: Tisanas frutales y moringa. | AH35: Efectivo | AI35: 500 | AJ35: Completa | AK35: 10 | AN35: Enjoy Time | AO35: Francisco Valencia | AP35: 3339582509 | AS35: Tisanas frutales y moringa. | AU35: Efectivo | AV35: 400 | AW35: Completa | AX35: 10 | AZ35: 1 | BB35: Glow | BC35: Alejandro Cantú | BD35: 3317314958 | BE35: 17314958 | BF35: glowstore.07@gmail.com | BG35: ropa de diseño independiente | BI35: Efectivo | BJ35: 187.5 | BK35: Media | BL35: 13c | BN35: 1 | BP35: Den Maya Invernaderos | BQ35: Yesica Delgado Díaz | BR35: 3311856312 | BT35: yeska_27@hotmail.com | BU35: Plantas, hierbas aromáticas, flores, árboles en maceta. | BW35: Efectivo | BX35: 375 | BY35: Completa | BZ35: 6 | CB35: 3 | CD35: La Ciudad de los Campos | CE35: Ángeles Muñoz | CF35: 3335591738 | CH35: mangelesmunoz@me.com | CI35: Quesos, aderezos. | CK35: Efectivo | CL35: 100 | CM35: Media | CN35: 4a | CP35: 4
A36: Gusto Gourmet | B36: Karen Alonso | C36: 3314412645 | F36: Salsas, verdura botanera, chimichurri, pesto. | H36: Efectivo | I36: 200 | J36: Media | K36: 2 | N36: Gaia EcoStore | O36: Viviana Torres | P36: 3318451485 | R36: vivianatorres@gaiaecostore.com | S36: Tienda de productos organicos. | T36: Sofía | U36: pendiente | V36: 50 | W36: Completa | X36: 24 | AA36: EVOO | AB36: Margarita Rodriguez | AC36: 3313600806 | AE36: dramarrod@hotmail.com | AH36: Efectivo | AI36: 50 | AJ36: Completa | AK36: 30 | AN36: EVOO | AO36: Margarita Rodriguez | AP36: 3313600806 | AR36: dramarrod@hotmail.com | AU36: Efectivo | AV36: 50 | AW36: Completa | AX36: 31 | AZ36: 1 | BB36: Gusto Gourmet | BC36: Karen Alonso | BD36: 3314412645 | BG36: Salsas, verdura botanera, chimichurri, pesto. | BI36: Efectivo | BJ36: 200 | BK36: Media | BL36: 3a | BN36: 2 | BP36: Eclectic | BQ36: Osvaldo López | BR36: 3312326066 | BT36: osvaldo_flb@hotmail.com | BU36: Playeras sublimadas | BV36: Gonzalo | BW36: Efectivo | BX36: 250 | BY36: Media | BZ36: 20a | CA36: N | CB36: 1 | CD36: Le Guttie | CE36: Mariel Gutierrez | CF36: 3311392611 | CH36: leguttie@gmail.com | CI36: manzanas cubiertas, fresas con chocolate | CK36: Efectivo | CL36: 200 | CM36: Media | CP36: 3
A37: Jamaitingas | B37: Arlene Sánchez | C37: 3334057358 | E37: miryana23@hotmail.com | F37: guisados a base de jamaica | H37: Efectivo | I37: 750 | J37: Media | K37: 15a | N37: Glow | O37: Alejandro Cantú | P37: 3317314958 | Q37: 17314958 | R37: glowstore.07@gmail.com | S37: ropa de diseño independiente | U37: Efectivo | V37: 750 | W37: Media | X37: 13b | AA37: Gaia EcoStore | AB37: Viviana Torres | AC37: 3318451485 | AE37: vivianatorres@gaiaecostore.com | AF37: Tienda de productos organicos. | AH37: Intercambio | AI37: 50 | AJ37: Completa | AK37: 4 | AN37: Gaia EcoStore | AO37: Viviana Torres | AP37: 3318451485 | AR37: vivianatorres@gaiaecostore.com | AS37: Tienda de productos organicos. | AU37: Efectivo | AV37: 50 | AW37: Completa | AX37: 4 | AZ37: 1 | BB37: Itacate | BC37: Swannie Díaz de León | BD37: 3310967806 | BF37: yolohtli@gmail.com | BG37: Granola, hummus, tabule, pan. | BI37: Efectivo | BJ37: 125 | BK37: Media | BL37: 14b | BN37: 1 | BP37: Eclock | BQ37: Edgar Torres | BR37: 3317246984 | BT37: eclock.relojes@hotmail.com | BU37: Relojes de madera | BW37: Efectivo | BX37: 200 | BY37: Media | BZ37: 24b | CB37: 1 | CD37: Liliana Jaime | CE37: Liliana Gutierrez | CF37: 3314103650 | CH37: lilianajaime78@gmail.com | CI37: ropa de diseño independiente | CJ37: Sofía | CK37: Efectivo | CL37: 200 | CM37: Ninguna | CN37: 10c | CP37: 4
A38: Klok | B38: María Luisa Álvarez Caloca | C38: 3336777441 | D38: 38231337 | E38: maria@xtal.com.mx | F38: Ilustración a base de primacolor. | G38: Gonzalo | H38: Efectivo | I38: 250 | J38: Media | K38: 19a | L38: N | N38: Jamaitingas | O38: Arlene Sánchez | P38: 3334057358 | R38: miryana23@hotmail.com | S38: guisados a base de jamaica | U38: Efectivo | V38: 750 | W38: Media | X38: 15a | AA38: Glow | AB38: Alejandro Cantú | AC38: 3317314958 | AD38: 17314958 | AE38: glowstore.07@gmail.com | AF38: ropa de diseño independiente | AH38: Efectivo | AI38: 187.5 | AJ38: Media | AK38: 13c | AN38: Gusto Gourmet | AO38: Karen Alonso | AP38: 3314412645 | AS38: Salsas, verdura botanera, chimichurri, pesto. | AU38: Efectivo | AV38: 200 | AW38: Media | AX38: 3a | AZ38: 1 | BB38: Jamaitingas | BC38: Arlene Sánchez | BD38: 3334057358 | BF38: miryana23@hotmail.com | BG38: guisados a base de jamaica | BI38: Falta | BJ38: 60 | BK38: Media | BN38: 2 | BP38: Enjoy Time | BQ38: Francisco Valencia | BR38: 3339582509 | BU38: Tisanas frutales y moringa. | BW38: Efectivo | BX38: 400 | BY38: Completa | BZ38: 10 | CB38: 3 | CD38: Lucy Cactus Company | CE38: Verónica Gil | CF38: 3311185434 | CH38: veronik339.vg@gmail.com | CI38: macetas de barro pintadas | CK38: Efectivo | CL38: 187.5 | CM38: Media | CN38: 6a | CP38: 4
A39: La Bee Organic | B39: Luis Elizondo | C39: 3331787364 | E39: labeeorganic@gmail.com | F39: bálsamo para labios | H39: Efectivo | I39: 750 | J39: Media | K39: 14b | N39: Klok | O39: María Luisa Álvarez Caloca | P39: 3336777441 | Q39: 38231337 | R39: maria@xtal.com.mx | S39: Ilustración a base de primacolor. | T39: Gonzalo | U39: Efectivo | V39: 200 | W39: Media | X39: 19a | AA39: Jamaitingas | AB39: Arlene Sánchez | AC39: 3334057358 | AE39: miryana23@hotmail.com | AF39: guisados a base de jamaica | AH39: Efectivo | AI39: 187.5 | AJ39: Media | AK39: 15a | AN39: Jamaitingas | AO39: Arlene Sánchez | AP39: 3334057358 | AR39: miryana23@hotmail.com | AS39: guisados a base de jamaica | AU39: Falta | AV39: 187.5 | AW39: Media | AZ39: 1 | BB39: Klok | BC39: María Luisa Álvarez Caloca | BD39: 3336777441 | BE39: 38231337 | BF39: maria@xtal.com.mx | BG39: Ilustración a base de primacolor. | BH39: Gonzalo | BI39: Efectivo | BJ39: 200 | BK39: Media | BL39: 19a | BN39: 2 | BP39: EVOO | BQ39: Margarita Rodriguez | BR39: 3313600806 | BT39: dramarrod@hotmail.com | BW39: Efectivo | BX39: 50 | BY39: Completa | BZ39: 30 | CB39: 3 | CD39: Mishu | CE39: Ella Cornejo | CF39: 3314415732 | CG39: 36275564 | CH39: ella.marina.cornejo@gmail.com | CI39: Armonizadores de espacios tejidos. | CJ39: Sofía | CK39: Efectivo | CL39: 187.5 | CM39: Media | CN39: 15b | CP39: 4
A40: Le Guttie | B40: Mariel Gutierrez | C40: 3311392611 | E40: leguttie@gmail.com | F40: manzanas cubiertas, fresas con chocolate | H40: Efectivo | I40: 750 | J40: Media | K40: 5b | N40: La Bee Organic | O40: Luis Elizondo | P40: 3331787364 | R40: labeeorganic@gmail.com | S40: bálsamo para labios | U40: Efectivo | V40: 750 | W40: Media | X40: 14b | AA40: Klok | AB40: María Luisa Álvarez Caloca | AC40: 3336777441 | AD40: 38231337 | AE40: maria@xtal.com.mx | AF40: Ilustración a base de primacolor. | AG40: Gonzalo | AH40: Efectivo | AI40: 200 | AJ40: Media | AK40: 5 | AN40: La Bee Organic | AO40: Luis Elizondo | AP40: 3331787364 | AR40: labeeorganic@gmail.com | AS40: bálsamo para labios | AU40: Efectivo | AV40: 187.5 | AW40: Media | AX40: 14a | AZ40: 1 | BB40: La Ciudad de los Campos | BC40: Ángeles Muñoz | BD40: 3335591738 | BF40: mangelesmunoz@me.com | BG40: Quesos, aderezos. | BI40: Efectivo | BJ40: 100 | BK40: Media | BL40: 4a | BN40: 2 | BP40: Gaia EcoStore | BQ40: Viviana Torres | BR40: 3318451485 | BT40: vivianatorres@gaiaecostore.com | BU40: Tienda de productos organicos. | BW40: Efectivo | BX40: 50 | BY40: Completa | BZ40: 11 | CB40: 2 | CD40: MontPao | CE40: Rodrigo Juárez Salazar | CF40: 3315508402 | CH40: borrego_gdl@hotmail.com | CI40: Blueberrys, mermeladas. | CJ40: Sofía | CK40: Efectivo | CL40: 187.5 | CM40: Media | CN40: 2a | CP40: 4
A41: Lovely Creations | B41: Luz Mantilla | C41: 3339683396 | E41: itza.barba@hp.com | H41: Efectivo | I41: 400 | J41: Completa | K41: 7 | N41: Le Guttie | O41: Mariel Gutierrez | P41: 3311392611 | R41: leguttie@gmail.com | S41: manzanas cubiertas, fresas con chocolate | U41: Efectivo | V41: 750 | W41: Media | X41: 10b | AA41: Korkas | AB41: Aranzazú Castillo | AC41: 3319582152 | AE41: aranza.dicastello@hotmail.com | AF41: sandalias artesanales | AH41: Efectivo | AI41: 200 | AJ41: Media | AK41: 16a | AN41: Le Guttie | AO41: Mariel Gutierrez | AP41: 3311392611 | AR41: leguttie@gmail.com | AS41: manzanas cubiertas, fresas con chocolate | AU41: Efectivo | AV41: 187.5 | AW41: Media | AX41: 9a | AZ41: 1 | BB41: Le Guttie | BC41: Mariel Gutierrez | BD41: 3311392611 | BF41: leguttie@gmail.com | BG41: manzanas cubiertas, fresas con chocolate | BI41: Falta | BJ41: 60 | BK41: Media | BN41: 2 | BP41: Glow | BQ41: Alejandro Cantú | BR41: 3317314958 | BS41: 17314958 | BT41: glowstore.07@gmail.com | BU41: ropa de diseño independiente | BW41: Efectivo | BX41: 200 | BY41: Ninguna | BZ41: 13c | CB41: 2 | CD41: Nacuii | CE41: Denis Ruan | CF41: 3339576724 | CH41: denis@nacuii.com | CI41: Productos de concha nacar y madreperla. | CJ41: Gonzalo | CK41: Efectivo | CL41: 200 | CM41: Media | CN41: 13a | CO41: N | CP41: 1
A42: Lucy Cactus Company | B42: Verónica Gil | C42: 3311185434 | E42: veronik339.vg@gmail.com | F42: macetas de barro pintadas | H42: Efectivo | I42: 200 | J42: Media | K42: 20a | N42: Libertas | O42: Luis Felipe Angulo | P42: 3310640389 | R42: lufac90@hotmail.com | S42: Licor de jamaica. | T42: Margarita | U42: pendiente | V42: 750 | W42: Media | X42: 16b | AA42: Le Guttie | AB42: Mariel Gutierrez | AC42: 3311392611 | AE42: leguttie@gmail.com | AF42: manzanas cubiertas, fresas con chocolate | AH42: Efectivo | AI42: 187.5 | AJ42: Media | AK42: 8b | AN42: Le Ve | AO42: Brenda de la Cruz | AP42: 3312088704 | AR42: bleutulip@hotmail.com | AS42: Quesos y leches veganos de semillas | AT42: Ceci | AU42: Efectivo | AV42: 200 | AW42: Media | AX42: 17a | AZ42: 1 | BB42: Le Ve | BC42: Brenda de la Cruz | BD42: 3312088704 | BF42: bleutulip@hotmail.com | BG42: Quesos y leches veganos de semillas | BH42: Ceci | BI42: Efectivo | BJ42: 200 | BK42: Media | BL42: 17a | BN42: 2 | BP42: Gusto Gourmet | BQ42: Karen Alonso | BR42: 3314412645 | BU42: Salsas, verdura botanera, chimichurri, pesto. | BW42: Efectivo | BX42: 200 | BY42: Media | BZ42: 9a | CB42: 3 | CD42: Organic Home | CE42: Viridiana Covarrubias | CF42: 3310408306 | CH42: organic_home@hotmail.com | CI42: orquídeas | CK42: Efectivo | CL42: 187.5 | CM42: Media | CN42: 4b | CP42: 4
A43: Luna Menstruarte | B43: Karime Hernández | C43: 3317071188 | E43: infolunamenstruarte@gmail.com | F43: Copas menstruales | H43: Efectivo | I43: 750 | J43: Media | K43: 8b | N43: Liliana Jaime | O43: Liliana Gutierrez | P43: 3314103650 | R43: lilianajaime78@gmail.com | U43: Efectivo | V43: 250 | W43: Ninguna | X43: 26a | AA43: Le Ve | AB43: Brenda de la Cruz | AC43: 3312088704 | AE43: bleutulip@hotmail.com | AF43: Quesos y leches veganos de semillas | AG43: Ceci | AH43: Efectivo | AI43: 250 | AJ43: Media | AK43: 17a | AN43: Liliana Jaime | AO43: Liliana Gutierrez | AP43: 3314103650 | AR43: lilianajaime78@gmail.com | AS43: ropa de diseño independiente | AT43: Sofía | AU43: Efectivo | AV43: 200 | AW43: Ninguna | AX43: 34c | AZ43: 1 | BB43: Liliana Jaime | BC43: Liliana Gutierrez | BD43: 3314103650 | BF43: lilianajaime78@gmail.com | BG43: ropa de diseño independiente | BH43: Sofía | BI43: Efectivo | BJ43: 200 | BK43: Ninguna | BL43: 31c | BN43: 2 | BP43: Happy Bakery | BQ43: Adriana Gutierrez Jaime | BR43: 3313386181 | BS43: 33652050 | BT43: adimigo@yahoo.com.mx | BU43: Galletas, donas y brownies | BV43: Sofía | BW43: Efectivo | BX43: 250 | BY43: Media | BZ43: 35b | CA43: N | CB43: 1 | CD43: Pacha Mama | CE43: Lilia Ibarra | CF43: 3333979927 | CG43: 36563118 | CH43: charly-22889@hotmail.com | CI43: Bisutaría y piedras naturales | CJ43: Sofía | CK43: Efectivo | CL43: 200 | CM43: Media | CP43: 2
A44: Mishu | B44: Ella Cornejo | C44: 3314415732 | D44: 36275564 | E44: ella.marina.cornejo@gmail.com | F44: Armonizadores de espacios tejidos. | G44: Sofía | H44: Efectivo | I44: 1000 | J44: Media | K44: 15b | L44: N | N44: Lovely Creations | O44: Luz Mantilla | P44: 3339683396 | R44: itza.barba@hp.com | T44: Cecibel | U44: Efectivo | V44: 400 | W44: Completa | X44: 7 | AA44: Lovely Creations | AB44: Luz Mantilla | AC44: 3339683396 | AE44: itza.barba@hp.com | AH44: Efectivo | AI44: 400 | AJ44: Completa | AK44: 7 | AN44: Lo Escencial de la Vida | AO44: Mary McPherson | AP44: 3333116669 | AQ44: 16557103 | AS44: Aceites esenciales. | AT44: Sofía | AU44: Efectivo | AV44: 250 | AW44: Media | AX44: 32b | AY44: N | AZ44: 1 | BB44: Lucy Cactus Company | BC44: Verónica Gil | BD44: 3311185434 | BF44: veronik339.vg@gmail.com | BG44: macetas de barro pintadas | BI44: Efectivo | BJ44: 187.5 | BK44: Media | BL44: 6a | BN44: 2 | BP44: Jamaitingas | BQ44: Arlene Sánchez | BR44: 3334057358 | BT44: miryana23@hotmail.com | BU44: guisados a base de jamaica | BW44: Efectivo | BX44: 200 | BY44: Media | BZ44: 15a | CB44: 3 | CD44: Perla Negra | CE44: Romina de la Parra | CF44: 3332003097 | CG44: 38103965 | CH44: perlanegra.ventas@hotmail.com | CI44: Arcilla termal volcánica, antifaz térmico de arcilla volcánica, piedra de origen volcánico, jabón artesanal de arcilla volcánica y romero. | CK44: Efectivo | CL44: 187.5 | CM44: Media | CN44: 8a | CP44: 2
A45: Ofelia Pozole | B45: Ana Rosales | D45: 38257028 | E45: quetzallicocone@hotmail.com | F45: Pozole vegetariano | H45: Efectivo | I45: 750 | J45: Media | K45: 10b | N45: Lucy Cactus Company | O45: Verónica Gil | P45: 3311185434 | R45: veronik339.vg@gmail.com | S45: macetas de barro pintadas | T45: Sofía | U45: Efectivo | V45: 200 | W45: Media | X45: 25a | AA45: Lucy Cactus Company | AB45: Verónica Gil | AC45: 3311185434 | AE45: veronik339.vg@gmail.com | AF45: macetas de barro pintadas | AH45: Efectivo | AI45: 187.5 | AJ45: Media | AK45: 6a | AN45: Lucy Cactus Company | AO45: Verónica Gil | AP45: 3311185434 | AR45: veronik339.vg@gmail.com | AS45: macetas de barro pintadas | AU45: Efectivo | AV45: 187.5 | AW45: Media | AX45: 6a | AZ45: 1 | BB45: Minerarte | BC45: Leonardo Dueñas | BD45: 3331878752 | BF45: lfalout26@gmail.com | BG45: lámparas de cuarzo | BH45: Sofía | BI45: Falta | BJ45: 60 | BK45: Media | BN45: 2 | BP45: Klok | BQ45: María Luisa Álvarez Caloca | BR45: 3336777441 | BS45: 38231337 | BT45: maria@xtal.com.mx | BU45: Ilustración a base de primacolor. | BV45: Gonzalo | BW45: Efectivo | BX45: 200 | BY45: Media | BZ45: 25a | CB45: 3 | CD45: Piña Palmera | CE45: Lula de Lara | CF45: 3311900294 | CH45: lula@pinapalmera.com | CI45: aguas naturales de frutas | CJ45: Sofía | CK45: Efectivo | CL45: 187.5 | CM45: Ninguna | CN45: 0 | CP45: 4
A46: Pangourmeti | B46: Mónica Herández | C46: 3314501114 | E46: monica@cosmosmkt.com | F46: Pan y galletas. | H46: Intercambio | I46: 0 | J46: Completa | K46: 4 | N46: Luna Menstruarte | O46: Karime Hernández | P46: 3317071188 | R46: infolunamenstruarte@gmail.com | S46: Copas menstruales | U46: Efectivo | V46: 750 | W46: Media | X46: 8b | AA46: Luna Menstruarte | AB46: Karime Hernández | AC46: 3317071188 | AE46: infolunamenstruarte@gmail.com | AF46: Copas menstruales | AH46: Efectivo | AI46: 187.5 | AJ46: Media | AK46: 9a | AN46: Luna Menstruarte | AO46: Karime Hernández | AP46: 3317071188 | AR46: infolunamenstruarte@gmail.com | AS46: Copas menstruales | AU46: Efectivo | AV46: 187.5 | AW46: Media | AX46: 8a | AZ46: 1 | BB46: Mishu | BC46: Ella Cornejo | BD46: 3314415732 | BE46: 36275564 | BF46: ella.marina.cornejo@gmail.com | BG46: Armonizadores de espacios tejidos. | BH46: Sofía | BI46: Efectivo | BJ46: 200 | BK46: Media | BL46: 15b | BN46: 2 | BP46: La Bee Organic | BQ46: Luis Elizondo | BR46: 3331787364 | BT46: labeeorganic@gmail.com | BU46: bálsamo para labios | BW46: Efectivo | BX46: 200 | BY46: Media | BZ46: 25b | CB46: 2 | CD46: Productos Gourmet | CE46: Victor Hugo Lamas | CF46: 3314112703 | CH46: victorlamasr@yahoo.com.mx | CK46: Efectivo | CL46: 200 | CM46: Media | CN46: 8b | CP46: 3
A47: Perla Negra | B47: Romina de la Parra | C47: 3332003097 | D47: 38103965 | E47: perlanegra.ventas@hotmail.com | F47: Arcilla termal volcánica, antifaz térmico de arcilla volcánica, piedra de origen volcánico, jabón artesanal de arcilla volcánica y romero. | H47: Banco | I47: 187.5 | J47: Media | K47: 6a | N47: Mielomex | O47: Joel Lopez | P47: 3310932686 | R47: karma_22@hotmail.com | U47: Efectivo | V47: 250 | W47: Media | X47: 23b | AA47: Minerarte | AB47: Leonardo Dueñas | AC47: 3331878752 | AE47: lfalout26@gmail.com | AF47: lámparas de cuarzo | AG47: Sofía | AH47: Efectivo | AI47: 200 | AJ47: Media | AK47: 31 | AN47: Lupita de la Peña | AO47: Lupita de la Peña | AP47: 3338099924 | AR47: lupitadelapena@gmail.com | AS47: galletas de avena, brownies y reposteria artesanal | AU47: Efectivo | AV47: 200 | AW47: Media | AX47: 34a | AZ47: 1 | BB47: MontPao | BC47: Rodrigo Juárez Salazar | BD47: 3315508402 | BF47: borrego_gdl@hotmail.com | BG47: Blueberrys, mermeladas. | BH47: Sofía | BI47: Efectivo | BJ47: 187.5 | BK47: Media | BL47: 2a | BN47: 2 | BP47: La Ciudad de los Campos | BQ47: Ángeles Muñoz | BR47: 3335591738 | BT47: mangelesmunoz@me.com | BU47: Quesos, aderezos. | BW47: Efectivo | BX47: 100 | BY47: Media | BZ47: 12a | CB47: 3 | CD47: Promaná | CE47: Manuel Mendez | CF47: 3334488380 | CG47: 36314024 | CH47: jmmu.97@gmail.com | CI47: Huevo orgánico de rancho, moringa. | CK47: Banco | CL47: 187.5 | CM47: Media | CN47: 18b | CP47: 3
A48: Productos Gourmet | B48: Victor Hugo Lamas | C48: 3314112703 | E48: victorlamasr@yahoo.com.mx | H48: Efectivo | I48: 200 | J48: Media | K48: 3b | N48: Milenium | O48: alfonso jimenez | P48: 3315549675 | R48: antiquemilenium@hotmail.com | U48: Efectivo | V48: 500 | W48: Completa | X48: 29 | AA48: Mishu | AB48: Ella Cornejo | AC48: 3314415732 | AD48: 36275564 | AE48: ella.marina.cornejo@gmail.com | AF48: Armonizadores de espacios tejidos. | AG48: Sofía | AH48: Efectivo | AI48: 200 | AJ48: Media | AK48: 15b | AN48: Klok | AO48: María Luisa Álvarez Caloca | AP48: 3336777441 | AQ48: 38231337 | AR48: maria@xtal.com.mx | AS48: Ilustración a base de primacolor. | AT48: Gonzalo | AU48: Efectivo | AV48: 200 | AW48: Media | AX48: 19a | AZ48: 1 | BB48: Nutri Antojos | BC48: Jorge González | BD48: 3335841961 | BF48: nutriantojos@outlook.com | BG48: Fruta y verdura deshidratada, nopal con chile. | BI48: Efectivo | BJ48: 200 | BK48: Media | BL48: 8b | BN48: 2 | BP48: Liliana Jaime | BQ48: Liliana Gutierrez | BR48: 3314103650 | BT48: lilianajaime78@gmail.com | BU48: ropa de diseño independiente | BV48: Sofía | BW48: Efectivo | BX48: 200 | BY48: Ninguna | BZ48: 35c | CB48: 3 | CD48: Quetzalli | CE48: Aura Rodriguez | CF48: 3317711276 | CG48: 3338244746 | CH48: pacoatlicue@hotmail.com | CI48: lámparas, aretes de cupcakes y postres, dijes de resina | CK48: Efectivo | CL48: 187.5 | CM48: Media | CN48: 17a | CP48: 4
A49: Productos Vegetarianos | B49: Zoé Ruelas SantaCruz | C49: 3331406846 | E49: psicozoe@hotmail.com | F49: Chorizo vegetariano, cochinita vegetariana y milanesas de trigo. | G49: Sofía | H49: Efectivo | I49: 250 | J49: Media | K49: 5a | L49: N | N49: Minerales Naturales | O49: Leonardo Dueñas | P49: 3331878752 | U49: Efectivo | V49: 250 | W49: Media | X49: 27b | AA49: MontPao | AB49: Rodrigo Juárez Salazar | AC49: 3315508402 | AE49: borrego_gdl@hotmail.com | AF49: Blueberrys, mermeladas. | AG49: Sofía | AH49: Efectivo | AI49: 250 | AJ49: Media | AK49: 2a | AN49: Minerarte | AO49: Leonardo Dueñas | AP49: 3331878752 | AR49: lfalout26@gmail.com | AS49: lámparas de cuarzo | AT49: Sofía | AU49: Efectivo | AV49: 200 | AW49: Media | AX49: 19b | AZ49: 1 | BB49: Organic Home | BC49: Viridiana Covarrubias | BD49: 3310408306 | BF49: organic_home@hotmail.com | BG49: orquídeas | BI49: Efectivo | BJ49: 187.5 | BK49: Media | BL49: 16a | BN49: 2 | BP49: Lucy Cactus Company | BQ49: Verónica Gil | BR49: 3311185434 | BT49: veronik339.vg@gmail.com | BU49: macetas de barro pintadas | BW49: Efectivo | BX49: 187.5 | BY49: Media | BZ49: 14a | CB49: 3 | CD49: Sagrante | CE49: Luis Felipe Angulo | CF49: 3310640389 | CH49: lufac90@hotmail.com | CI49: Licor de jamaica. | CK49: Efectivo | CL49: 187.5 | CM49: Media | CN49: 12b | CP49: 4
A50: Promaná | B50: Manuel Mendez | C50: 3334488380 | D50: 36314024 | E50: jmmu.97@gmail.com | F50: Huevo orgánico de rancho, moringa. | H50: Banco | I50: 1740 | J50: Completa | K50: 22 | N50: Mishu | O50: Ella Cornejo | P50: 3314415732 | Q50: 36275564 | R50: ella.marina.cornejo@gmail.com | S50: Armonizadores de espacios tejidos. | T50: Sofía | U50: Efectivo | V50: 1000 | W50: Media | X50: 15b | AA50: Piña Palmera | AB50: Lula de Lara | AC50: 3311900294 | AE50: lula@pinapalmera.com | AF50: aguas naturales de frutas | AG50: Sofía | AH50: Efectivo | AI50: 187.5 | AJ50: Media | AK50: 0 | AN50: Mishu | AO50: Ella Cornejo | AP50: 3314415732 | AQ50: 36275564 | AR50: ella.marina.cornejo@gmail.com | AS50: Armonizadores de espacios tejidos. | AT50: Sofía | AU50: Efectivo | AV50: 200 | AW50: Media | AX50: 15 | AZ50: 1 | BB50: Piña Palmera | BC50: Lula de Lara | BD50: 3311900294 | BF50: lula@pinapalmera.com | BG50: aguas naturales de frutas | BH50: Sofía | BI50: Efectivo | BJ50: 187.5 | BK50: Media | BL50: 0 | BN50: 2 | BP50: Luna Menstruarte | BQ50: Karime Hernández | BR50: 3317071188 | BT50: infolunamenstruarte@gmail.com | BU50: Copas menstruales | BW50: Efectivo | BX50: 200 | BY50: Media | BZ50: 18b | CB50: 1 | CD50: Sáname | CE50: Sergio Álvarez | CF50: 3312176844 | CH50: sergio-alvarez61@hotmail.com | CI50: Productos derivados de la miel | CK50: Efectivo | CL50: 187.5 | CM50: Media | CN50: 2b | CP50: 4
A51: Quetzalli | B51: Aura Rodriguez | C51: 3317711276 | D51: 3338244746 | E51: pacoatlicue@hotmail.com | F51: lámparas, aretes de cupcakes y postres, dijes de resina | H51: Efectivo | I51: 750 | J51: Media | K51: 19b | N51: Ofelia Pozole | O51: Ana Rosales | Q51: 38257028 | R51: quetzallicocone@hotmail.com | S51: Pozole vegetariano | U51: Efectivo | V51: 750 | W51: Media | X51: 18a | AA51: Promaná | AB51: Manuel Mendez | AC51: 3334488380 | AD51: 36314024 | AE51: jmmu.97@gmail.com | AF51: Huevo orgánico de rancho, moringa. | AH51: Banco | AI51: 375 | AJ51: Completa | AK51: 22 | AN51: MontPao | AO51: Rodrigo Juárez Salazar | AP51: 3315508402 | AR51: borrego_gdl@hotmail.com | AS51: Blueberrys, mermeladas. | AT51: Sofía | AU51: Efectivo | AV51: 200 | AW51: Media | AX51: 2a | AZ51: 1 | BB51: Productos Gourmet | BC51: Victor Hugo Lamas | BD51: 3314112703 | BF51: victorlamasr@yahoo.com.mx | BI51: Efectivo | BJ51: 200 | BK51: Media | BL51: 22a | BN51: 2 | BP51: Mishu | BQ51: Ella Cornejo | BR51: 3314415732 | BS51: 36275564 | BT51: ella.marina.cornejo@gmail.com | BU51: Armonizadores de espacios tejidos. | BV51: Sofía | BW51: Efectivo | BX51: 187.5 | BY51: Media | BZ51: 15b | CB51: 3 | CD51: Sempiterna | CE51: Eugenia Sánchez | CF51: 3311802665 | CH51: es.t-70@hotmail.com | CI51: Dijes de plata | CK51: Efectivo | CL51: 250 | CM51: Media | CN51: 17b | CP51: 2
A52: Sempiterna | B52: Eugenia Sánchez | C52: 3311802665 | E52: es.t-70@hotmail.com | F52: Dijes de plata | H52: Efectivo | I52: 750 | J52: Media | K52: 6b | N52: Productos Gourmet | O52: Victor Hugo Lamas | P52: 3314112703 | R52: victorlamasr@yahoo.com.mx | U52: Efectivo | V52: 200 | W52: Media | X52: 18b | AA52: Quetzalli | AB52: Aura Rodriguez | AC52: 3317711276 | AD52: 3338244746 | AE52: pacoatlicue@hotmail.com | AF52: lámparas, aretes de cupcakes y postres, dijes de resina | AH52: Efectivo | AI52: 187.5 | AJ52: Media | AK52: 21a | AN52: Nutri Antojos | AO52: Jorge González | AP52: 3335841961 | AR52: nutriantojos@outlook.com | AS52: Fruta y verdura deshidratada, nopal con chile. | AU52: Efectivo | AV52: 200 | AW52: Media | AX52: 33a | AZ52: 1 | BB52: Promaná | BC52: Manuel Mendez | BD52: 3334488380 | BE52: 36314024 | BF52: jmmu.97@gmail.com | BG52: Huevo orgánico de rancho, moringa. | BI52: Banco | BJ52: 187.5 | BK52: Media | BL52: 22b | BN52: 2 | BP52: MontPao | BQ52: Rodrigo Juárez Salazar | BR52: 3315508402 | BT52: borrego_gdl@hotmail.com | BU52: Blueberrys, mermeladas. | BV52: Sofía | BW52: Efectivo | BX52: 187.5 | BY52: Media | BZ52: 8a | CB52: 3 | CD52: Sufiz | CE52: Maye Betancourt | CF52: 3317109196 | CG52: 15967909 | CH52: mayedapa@hotmail.com | CI52: palanquetas, granola | CK52: Efectivo | CL52: 190 | CM52: Media | CN52: 18a | CP52: 4
A53: Sufiz | B53: Maye Betancourt | C53: 3317109196 | D53: 15967909 | E53: mayedapa@hotmail.com | F53: palanquetas, granola | H53: Efectivo | I53: 750 | J53: Media | K53: 16b | N53: Promaná | O53: Manuel Mendez | P53: 3334488380 | Q53: 36314024 | R53: jmmu.97@gmail.com | S53: Huevo orgánico de rancho, moringa. | U53: Banco | V53: 1740 | W53: Completa | X53: 20 | AA53: Sagrante | AB53: Luis Felipe Angulo | AC53: 3310640389 | AE53: lufac90@hotmail.com | AF53: Licor de jamaica. | AH53: Efectivo | AI53: 187.5 | AJ53: Media | AK53: 14b | AN53: Organic Home | AO53: Viridiana Covarrubias | AP53: 3310408306 | AR53: organic_home@hotmail.com | AS53: orquídeas | AU53: Efectivo | AV53: 187.5 | AW53: Media | AX53: 16a | AZ53: 1 | BB53: Quetzalli | BC53: Aura Rodriguez | BD53: 3317711276 | BE53: 3338244746 | BF53: pacoatlicue@hotmail.com | BG53: lámparas, aretes de cupcakes y postres, dijes de resina | BI53: Efectivo | BJ53: 187.5 | BK53: Media | BL53: 21a | BN53: 2 | BP53: Nutri Antojos | BQ53: Jorge González | BR53: 3335841961 | BT53: nutriantojos@outlook.com | BU53: Fruta y verdura deshidratada, nopal con chile. | BW53: Efectivo | BX53: 200 | BY53: Media | BZ53: 22b | CB53: 3 | CD53: Vihanta Natura | CE53: Valentina Bontempi | CF53: 3315398142 | CH53: bvale_81@yahoo.it | CI53: cremas a base de extractos y aceites naturales | CK53: Efectivo | CL53: 200 | CM53: Media | CN53: 16b | CP53: 4
A54: Tochtli | B54: Adrián Gutiérrez | C54: 3317440064 | E54: tochtli_desodorante@hotmail.com | F54: Talco desodorante, desodorante rolo, desodorante spray, shampoo, crema para afeitar, pasta de dientes, talco para pies. | I54: 200 | J54: Media | K54: 8a | N54: Quetzalli | O54: Aura Rodriguez | P54: 3317711276 | Q54: 3338244746 | R54: pacoatlicue@hotmail.com | S54: lámparas, aretes de cupcakes y postres, dijes de resina | U54: Efectivo | V54: 750 | W54: Media | X54: 21a | AA54: Sáname | AB54: Sergio Álvarez | AC54: 3312176844 | AE54: sergio-alvarez61@hotmail.com | AF54: Productos derivados de la miel | AH54: Efectivo | AI54: 250 | AJ54: Media | AK54: 2b | AN54: Piña Palmera | AO54: Lula de Lara | AP54: 3311900294 | AR54: lula@pinapalmera.com | AS54: aguas naturales de frutas | AT54: Sofía | AU54: Efectivo | AV54: 187.5 | AW54: Media | AX54: 0b | AZ54: 1 | BB54: Sagrante | BC54: Luis Felipe Angulo | BD54: 3310640389 | BF54: lufac90@hotmail.com | BG54: Licor de jamaica. | BI54: Efectivo | BJ54: 187.5 | BK54: Media | BL54: 20b | BN54: 2 | BP54: Oilstrich | BQ54: Sergio Curiel | BR54: 3315207707 | BS54: 18155093 | BT54: oilstrichproducts@gmail.com | BU54: cremas a base de avestruz | BW54: Falta | BX54: 0 | BY54: Media | BZ54: 34a | CD54: Yerba Sana | CE54: Julieta Hernández | CF54: 3310849639 | CG54: 36470293 | CH54: yerbasana@hotmail.com | CI54: Chía, aceite de coco, sal orgánica. | CK54: Efectivo | CL54: 125 | CM54: Media | CN54: 14a | CP54: 4
A55: Vihanta Natura | B55: Valentina Bontempi | C55: 3315398142 | E55: bvale_81@yahoo.it | F55: cremas a base de extractos y aceites naturales | H55: Efectivo | I55: 750 | J55: Media | K55: 11b | N55: Sáname | O55: Sergio Álvarez | P55: 3312176844 | R55: sergio-alvarez61@hotmail.com | U55: Efectivo | V55: 500 | W55: Completa | X55: 4 | AA55: Sufiz | AB55: Maye Betancourt | AC55: 3317109196 | AD55: 15967909 | AE55: mayedapa@hotmail.com | AF55: palanquetas, granola | AH55: Efectivo | AI55: 187.5 | AJ55: Media | AK55: 19b | AN55: Productos Gourmet | AO55: Victor Hugo Lamas | AP55: 3314112703 | AR55: victorlamasr@yahoo.com.mx | AU55: Efectivo | AV55: 200 | AW55: Media | AX55: 21a | AZ55: 1 | BB55: Sáname | BC55: Sergio Álvarez | BD55: 3312176844 | BF55: sergio-alvarez61@hotmail.com | BG55: Productos derivados de la miel | BI55: Efectivo | BJ55: 187.5 | BK55: Media | BL55: 2b | BN55: 2 | BP55: Organic Home | BQ55: Viridiana Covarrubias | BR55: 3310408306 | BT55: organic_home@hotmail.com | BU55: orquídeas | BW55: Efectivo | BX55: 187.5 | BY55: Media | BZ55: 23a | CB55: 3
A56: Virgo | B56: Victor Ortega | C56: 3314117605 | D56: 38134694 | E56: virgonutricion@hotmail.com | F56: Mermeladas, yoghurt. | H56: Efectivo | I56: 200 | J56: Media | K56: 20b | N56: Sufiz | O56: Maye Betancourt | P56: 3317109196 | Q56: 15967909 | R56: mayedapa@hotmail.com | S56: palanquetas, granola | U56: Efectivo | V56: 750 | W56: Media | X56: 26b | AA56: Vihanta Natura | AB56: Valentina Bontempi | AC56: 3315398142 | AE56: bvale_81@yahoo.it | AF56: cremas a base de extractos y aceites naturales | AH56: Efectivo | AI56: 187.5 | AJ56: Media | AK56: 18a | AN56: Promaná | AO56: Manuel Mendez | AP56: 3334488380 | AQ56: 36314024 | AR56: jmmu.97@gmail.com | AS56: Huevo orgánico de rancho, moringa. | AU56: Banco | AV56: 375 | AW56: Completa | AX56: 22 | AZ56: 1 | BB56: Sempiterna | BC56: Eugenia Sánchez | BD56: 3311802665 | BF56: es.t-70@hotmail.com | BG56: Dijes de plata | BI56: Efectivo | BJ56: 250 | BK56: Media | BL56: 18a | BN56: 1 | BP56: Pacha Mama | BQ56: Lilia Ibarra | BR56: 3333979927 | BS56: 36563118 | BT56: charly-22889@hotmail.com | BU56: Bisutaría y piedras naturales | BV56: Sofía | BW56: Efectivo | BX56: 250 | BY56: Media | BZ56: 32a | CA56: N | CB56: 1
...

Sheet Hoja2

Sheet Reclamo de equipaje rediseñado
A1: # Vuelo | B1: LÍNEA AÉREA | C1: HORA AERONAVE POSICIÓN | D1: HORA PRIMER MALETA | E1: Tiempo | F1: HORA ÚLTIMA MALETA | G1: Tiempo2 | H1: FECHA | I1: Procedencia | J1: Equipo | K1: Capacidad | L1: Nacional/ Internacional | M1: Mes
A2: 8851 | B2: =VLOOKUP(Tabla6[[#This Row],['# Vuelo]],'Validacion reclamo de equipaje'!P:Q,2,0) -> MEXICO AEREO | C2: 0.87152778 | D2: 0.91111111 | E2: ='Reclamo de equipaje rediseñado'!$D2-'Reclamo de equipaje rediseñado'!$C2 -> 0.039583333 | F2: 0.91666667 | G2: =F2-D2 -> 0.0055555556 | H2: 41721 | I2: MEX | J2: ER4 | K2: =VLOOKUP(J2,'Validacion reclamo de equipaje'!L:M,2,0) -> 50 | L2: =VLOOKUP(I2,'Validacion reclamo de equipaje'!H:I,2,0) -> Nacional | M2: Marzo
A3: 8702 | B3: =VLOOKUP(Tabla6[[#This Row],['# Vuelo]],'Validacion reclamo de equipaje'!P:Q,2,0) -> MEXICO AEREO | C3: 0.63402778 | D3: 0.64027778 | E3: ='Reclamo de equipaje rediseñado'!$D3-'Reclamo de equipaje rediseñado'!$C3 -> 0.00625 | F3: 0.64861111 | G3: =F3-D3 -> 0.0083333333 | H3: 41725 | I3: QRO | J3: ER4 | K3: =VLOOKUP(J3,'Validacion reclamo de equipaje'!L:M,2,0) -> 50 | L3: =VLOOKUP(I3,'Validacion reclamo de equipaje'!H:I,2,0) -> Nacional | M3: Marzo
A4: 3120 | B4: =VLOOKUP(Tabla6[[#This Row],['# Vuelo]],'Validacion reclamo de equipaje'!P:Q,2,0) -> MEXICO AEREO | C4: 0.44027778 | D4: 0.44791667 | E4: ='Reclamo de equipaje rediseñado'!$D4-'Reclamo de equipaje rediseñado'!$C4 -> 0.0076388889 | F4: 0.45208333 | G4: =F4-D4 -> 0.0041666667 | H4: 41726 | I4: QRO | J4: No encontrado, probable error | K4: =VLOOKUP(J4,'Validacion reclamo de equipaje'!L:M,2,0) -> #N/A | L4: =VLOOKUP(I4,'Validacion reclamo de equipaje'!H:I,2,0) -> Nacional | M4: Marzo
A5: 2811 | B5: =VLOOKUP(Tabla6[[#This Row],['# Vuelo]],'Validacion reclamo de equipaje'!P:Q,2,0) -> MEXICO AEREO | C5: 0.59583333 | D5: 0.59861111 | E5: ='Reclamo de equipaje rediseñado'!$D5-'Reclamo de equipaje rediseñado'!$C5 -> 0.0027777778 | F5: 0.60416667 | G5: =F5-D5 -> 0.0055555556 | H5: 41722 | I5: QRO | J5: No encontrado, probable error | K5: =VLOOKUP(J5,'Validacion reclamo de equipaje'!L:M,2,0) -> #N/A | L5: =VLOOKUP(I5,'Validacion reclamo de equipaje'!H:I,2,0) -> Nacional | M5: Marzo
